Workbook

Sheet Scenario Matrix
A1: ODOO INCENTIVE SETUP – SCENARIO MATRIX
A2: ID | B2: Scenario/Business Rule | C2: Trigger / Driver / Input | D2: Odoo Setup/Object | E2: Calculation / Logic | F2: Expected Result | G2: Standard Odoo | H2: Customization | I2: Priority | J2: Discussion
A3: S01 | B3: Sales target (incentive-based) assigned to active sales team | C3: Active salesperson + branch + period | D3: Sales Team / Salesperson + Incentive Target table | E3: Target is stored by salesperson/team and incentive period | F3: Each salesperson has one valid target for the period | G3: Yes | H3: No | I3: Critical | J3: VIF have prepared target per sales person in excel
A4: S02 | B4: Branch target cascaded to individual salespersons | C4: Branch target + FTE allocation | D4: Incentive Target Allocation | E4: Individual target = branch target × FTE / total eligible FTE | F4: Target automatically allocated to eligible team members | G4: No | H4: Yes | I4: Critical | J4: Do we want to set the rule for any movement and/or dynamic?
A5: S03 | B5: Incentive-based target vs bonus-based target | C5: Incentive-based target = original target for active sales team Bonus-based target = Distributed-target cascaded from resigned team | D5: Incentive Target table | E5: Each sales person has 2 buckets: - Incentive-based bucket = predefined - Bonus-based bucket = Dynamic -- changes derived from sales team movement | F5: System can calculate mixed scenario | G5: No | H5: Yes | I5: Critical | J5: Need to prepare 2 buckets for each sales person
A6: S04 | B6: Sequential eligibility | C6: Sales achievement % | D6: Incentive Rule / Tier table | E6: Tier Level | Sales Achievement | Incentive Payout Allocation Tier 0 | <=75% | 0% Tier 1 | 75-84.9% | 40% Tier 2 | 85-89.9% | 80% Tier 3 | 90-99.9% | 90% Tier 4 | 100-109.9% | 100% Tier 5 | >=110% | 105% | F6: Eligibility based on sales achievement, both individual and branch, with total sales Correct allocation rate selected automatically | G6: No | H6: Yes | I6: Critical | J6: Total sales applied for all paid invoices with no limit to specific discount rule. If sales lines had >35% discount, will be included in sales achievement eligibility sequence 1
A7: S05 | B7: Base incentive rate | C7: Eligible tier | D7: Incentive Rule | E7: Base rate = 0.75% of eligible sales achievement | F7: Rate is multiplied by eligible fully paid invoice with max discount 35% per sales lines | G7: No | H7: Yes | I7: Critical | J7: Sequential rules applied
A8: S06 | B8: Individual + branch incentive | C8: Eligible revenue + tier | D8: Incentive Calculation | E8: Branch incentive and individual incentive calculated separately, then summed | F8: Total incentive = branch + individual | G8: No | H8: Yes | I8: High | J8: Provide tagging "Eligible | Not Eligible" for each month period
A9: S07 | B9: 35% maximum discount eligibility | C9: Sales order/invoice line discount | D9: Sales Order Line validation / incentive eligibility flag | E9: Only invoice lines with discount <=35% are eligible | F9: Any invoice lines with discount exceeded 35% will be excluded from incentive calculation | G9: No | H9: Yes | I9: Critical
A10: S08 | B10: Fully paid historical invoices generate incentive | C10: Invoice payment status + original invoice month | D10: Invoice / Payment / Incentive Transaction | E10: Eligible invoice remains linked to original incentive month; payout becomes eligible when payment condition is met | F10: Payout is calculated based on any sales invoice fully paid in current period Historical invoice can enter current payout calculation with respective eligibility sales achievement | G10: Partial | H10: Yes | I10: Critical | J10: Sequential rules applied
A11: S09 | B11: Multi-iteration for prior-period invoices | C11: Unpaid invoice from prior month becomes fully paid Partial paid have to be excluded | D11: Incentive Transaction / Payment reconciliation | E11: Recalculate/append eligible transaction when payment occurs | F11: Prior-period invoice is recognized without losing original period tag | G11: No | H11: Yes | I11: Critical | J11: Refer to month tagging "Eligible | Not Eligible"
A12: S10 | B12: Refund / cancellation - customer initiated | C12: Refund status + stock type | D12: Credit Note / Refund + Incentive Transaction | E12: Apply refund policy according to stock and initiator; reverse/adjust incentive transaction | F12: No double payout; adjustment traceable | G12: Partial | H12: Yes | I12: Critical | J12: Current period sales achievement shall be deducted by sales refund from historical period
A13: S11 | B13: Refund policy: available stock / customer | C13: Refund event | D13: Refund Policy matrix | E13: Customer + available stock = 99% refund; customer + indent/WIP follows configured policy | F13: Correct refund and incentive reversal | G13: No | H13: Yes | I13: High
A14: S12 | B14: Refund initiated by VIF | C14: Refund event + initiator | D14: Refund Policy matrix | E14: Use agreement-based refund policy | F14: Refund follows agreed exception rule | G14: No | H14: Yes | I14: High
A15: S13 | B15: Resignation / vacant position | C15: Employee inactive / resignation date | D15: Employee + Incentive Target Allocation | E15: Vacant target redistributed by FTE to active salespersons until replacement joins | F15: Remaining team target increases automatically | G15: No | H15: Yes | I15: Critical
A16: S14 | B16: New hire mid-month | C16: Employee join date | D16: Employee + Incentive Target Allocation | E16: Prorate target based on active days/month | F16: New hire receives prorated target and incentive eligibility | G16: No | H16: Yes | I16: Critical
A17: S15 | B17: Target movement after resignation | C17: Resignation date + replacement date | D17: Target Movement Log | E17: Split target by effective dates and reallocate balance | F17: Audit trail shows original, transferred and prorated target | G17: No | H17: Yes | I17: Critical
A18: S16 | B18: Scenario 1: full incentive-based target | C18: Scenario selector = Full Incentive | D18: Scenario Engine | E18: All target assigned to incentive bucket; apply 0.75% base rate | F18: Incentive payout calculated under Scenario 1 | G18: No | H18: Yes | I18: High
A19: S17 | B19: Scenario 2: mixed target (incentive-based & bonus-based) | C19: Scenario selector = Mixed | D19: Scenario Engine | E19: Incentive target + bonus target; incentive rate 0.75%, bonus rate 1.00% | F19: System calculates two payout streams and total | G19: No | H19: Yes | I19: Critical
A20: S18 | B20: Tier 5 not applicable in mixed scenario | C20: Mixed scenario + achievement >=110% | D20: Rule condition | E20: Do not apply 105% tier to incentive portion when mixed scenario is active | F20: Correct payout per policy | G20: No | H20: Yes | I20: High | J20: Condition for mixed target: Incentive-based achieved 100%, any excess will be considered as bonus-target
A21: S19 | B21: Salesperson visibility | C21: Logged-in salesperson | D21: Odoo access rights / dashboard | E21: User sees own target, achievement and calculated incentive; not tax-adjusted payout | F21: Self-service visibility | G21: Partial | H21: Yes | I21: High | J21: Odoo payout calculation act as reference for payslip calculation Any respective taxes calculated separately outside the system
A22: S20 | B22: Manager visibility | C22: Manager hierarchy | D22: Security groups + reporting domain | E22: Manager sees subordinate performance and incentive | F22: C-level consist of CEO and Head of Sales | G22: Partial | H22: Yes | I22: High
A23: S21 | B23: Period eligibility tagging | C23: Incentive month | D23: Incentive Period master | E23: Each incentive transaction stores incentive month, source invoice month and payment month | F23: Eligible months can be traced | G23: No | H23: Yes | I23: Critical | J23: Tagging month is crucial
A24: S22 | B24: Audit trail | C24: Any target/rule/calculation change | D24: Chatter / log + calculation snapshot | E24: Freeze approved calculation version | F24: Finance can reconcile and explain payout | G24: Partial | H24: Yes | I24: Critical | J24: When finance lock the accounting period, payout calculation shall final and can't change overtime

Sheet Sequential Rule
B1: Sequential Condition
B3: Sequential ID | C3: Sequential Condition | D3: Rule ID | E3: Rule Condition | F3: Condition | I3: Notes
F4: Base Rate | G4: Allocation | H4: Payout
B5: SQ1 | C5: Total sales achievement (Actual vs Target) with no restriction (include non-paid and discount >35%) | D5: T0 | E5: Tier 0 = Achievement <=75% | F5: 0 | G5: 0 | H5: =F5*G5 -> 0 | I5: Not eligible
B6: SQ1 | D6: T1 | E6: Tier 1 = 75%–84.9% | F6: 0.0075 | G6: 0.4 | H6: =F6*G6 -> 0.003 | I6: Of eligible revenue
B7: SQ1 | D7: T2 | E7: Tier 2 = 85%–89.9% | F7: 0.0075 | G7: 0.8 | H7: =F7*G7 -> 0.006 | I7: Of eligible revenue
B8: SQ1 | D8: T3 | E8: Tier 3 = 90%–99.9% | F8: 0.0075 | G8: 0.9 | H8: =F8*G8 -> 0.00675 | I8: Of eligible revenue
B9: SQ1 | D9: T4 | E9: Tier 4 = 100%–109.9% | F9: 0.0075 | G9: 1 | H9: =F9*G9 -> 0.0075 | I9: Of eligible revenue
B10: SQ1 | D10: T5 | E10: Tier 5 = Achievement >=110% | F10: 0.0075 | G10: 1.05 | H10: =F10*G10 -> 0.007875 | I10: Full incentive scenario only
B11: SQ2 | C11: Sales lines with max discount 35% are eligible | D11: D1 | E11: Invoice line discount <=35% | F11: Eligible | I11: Eligibility evaluated at item-line level
B12: SQ2 | D12: D2 | E12: Invoice line discount >35% | F12: Not eligible | I12: Exclude only affected line
B13: SQ3 | C13: Payment status | D13: P1 | E13: Payment status = Fully Paid | F13: Eligible for payout | I13: Depending on configured payment basis
B14: SQA | C14: Additional circumstance on top of sequential | D14: R1 | E14: Refund/cancel | F14: Adjustment / reversal | I14: Must retain source incentive transaction
B15: SQA | D15: N1 | E15: New hire mid-month | F15: Prorated | I15: Use effective active days
B16: SQA | D16: V1 | E16: Vacant/resigned position | F16: Redistribute | I16: Based on FTE among eligible active salespersons

Sheet Business Use Case
B1: Business Use Case
D3: As per JULY
B4: Sales Team | D4: Employment Status | E4: Sequence Condition | F4: Condition | G4: May | H4: June | I4: July | J4: August | K4: Notes | L4: UAT # | M4: Reference Cell
B5: A | C5: Jakarta | D5: Resigned | F5: Incentive-Based Target Sales | G5: 100000000 | H5: 100000000 | I5: 100000000 | J5: 100000000
F6: Bonus-Based Target Sales | G6: 0 | H6: 0 | I6: 0 | J6: 0
F7: Actual Sales | G7: 70000000 | H7: 65000000 | I7: 0 | J7: 0
F8: Sales Return Prior/Current in June | G8: 0 | H8: 0 | I8: 0 | J8: 0
F9: Net Sales | G9: 70000000 | H9: =H7-G8 -> 65000000 | I9: 0 | J9: 0
E10: Sequence 1 | F10: Incentive Tier | G10: =_xlfn.IFS((G9/G5)<75%,"Tier 0",AND((G9/G5)>=75%,(G9/G5)<85%),"Tier 1",AND((G9/G5)>=85%,(G9/G5)<90%),"Tier 2",AND((G9/G5)>=90%,(G9/G5)<100%),"Tier 3",AND((G9/G5)>=100%,(G9/G5)<110%),"Tier 4",(G9/G5)>=110%,"Tier 5") -> Tier 0 | H10: =_xlfn.IFS((H9/H5)<75%,"Tier 0",AND((H9/H5)>=75%,(H9/H5)<85%),"Tier 1",AND((H9/H5)>=85%,(H9/H5)<90%),"Tier 2",AND((H9/H5)>=90%,(H9/H5)<100%),"Tier 3",AND((H9/H5)>=100%,(H9/H5)<110%),"Tier 4",(H9/H5)>=110%,"Tier 5") -> Tier 0 | I10: Resigned as per 30 June | J10: Resigned as per 30 June | K10: Auto-calculation | L10: TC01 | M10: F11
E11: Sequence 2 | F11: Eligible Achievement Incentive | G11: 65000000 | H11: 40000000
E12: Sequence 3 | F12: Paid invoice previous month | G12: 0 | H12: 10000000
F13: Paid invoice in current month | G13: 45000000 | H13: 40000000 | I13: 0 | J13: 0 | K13: Auto-calculation
F14: Incentive Payout Previous Month | G14: 0 | H14: =_xlfn.IFS(G10="Tier 0",H12*'Sequential Rule'!$H$5,G10="Tier 1",H12*'Sequential Rule'!$H$6,G10="Tier 2",H12*'Sequential Rule'!$H$7,G10="Tier 3",H12*'Sequential Rule'!$H$8,G10="Tier 4",H12*'Sequential Rule'!$H$9,G10="Tier 5",H12*'Sequential Rule'!$H$10) -> 0 | K14: Auto-calculation
F15: Incentive Payout Current Month | G15: =_xlfn.IFS(G10="Tier 0",G13*'Sequential Rule'!$H$5,'Business Use Case'!G10="Tier 1",'Business Use Case'!G13*'Sequential Rule'!$H$6,'Business Use Case'!G10="Tier 2",'Business Use Case'!G13*'Sequential Rule'!$H$7,'Business Use Case'!G10="Tier 3",'Business Use Case'!G13*'Sequential Rule'!$H$8,'Business Use Case'!G10="Tier 4",'Business Use Case'!G13*'Sequential Rule'!$H$9,'Business Use Case'!G10="Tier 5",'Business Use Case'!G13*'Sequential Rule'!$H$10) -> 0 | H15: =_xlfn.IFS(H10="Tier 0",H13*'Sequential Rule'!$H$5,'Business Use Case'!H10="Tier 1",'Business Use Case'!H13*'Sequential Rule'!$H$6,'Business Use Case'!H10="Tier 2",'Business Use Case'!H13*'Sequential Rule'!$H$7,'Business Use Case'!H10="Tier 3",'Business Use Case'!H13*'Sequential Rule'!$H$8,'Business Use Case'!H10="Tier 4",'Business Use Case'!H13*'Sequential Rule'!$H$9,'Business Use Case'!H10="Tier 5",'Business Use Case'!H13*'Sequential Rule'!$H$10) -> 0 | I15: Resigned as per 30 June | J15: Resigned as per 30 June | K15: Auto-calculation
F16: Total Incentive Payout | G16: =SUM(G14:G15) -> 0 | H16: =SUM(H14:H15) -> 0 | K16: Auto-calculation
F17: Eligible Achievement Bonus | G17: 0 | H17: 0 | I17: Resigned as per 30 June | J17: Resigned as per 30 June | K17: Auto-calculation
F18: Bonus Payout | G18: 0 | H18: 0 | I18: Resigned as per 30 June | J18: Resigned as per 30 June | K18: Auto-calculation
B19: B | C19: Jakarta | D19: Active | F19: Incentive-Based Target Sales | G19: 100000000 | H19: 100000000 | I19: 100000000 | J19: 100000000
F20: Bonus-Based Target Sales | G20: 0 | H20: 0 | I20: =I5/COUNTA($D$19:$D$43) -> 50000000 | J20: =($J$5-$J$61)/COUNTA($C$19:$C$46) -> 30000000
F21: Actual Sales | G21: 90000000 | H21: 100000000 | I21: 145000000 | J21: 80000000
F22: Sales Return Prior/Current in June | G22: 11000000 | H22: 0 | I22: 0 | J22: 0
F23: Net Sales | G23: 86000000 | H23: =H21-G22-H22 -> 89000000 | I23: =I21-I22 -> 145000000 | J23: 95000000
E24: Sequence 1 | F24: Incentive Tier | G24: =_xlfn.IFS((G23/G19)<75%,"Tier 0",AND((G23/G19)>=75%,(G23/G19)<85%),"Tier 1",AND((G23/G19)>=85%,(G23/G19)<90%),"Tier 2",AND((G23/G19)>=90%,(G23/G19)<100%),"Tier 3",AND((G23/G19)>=100%,(G23/G19)<110%),"Tier 4",(G23/G19)>=110%,"Tier 5") -> Tier 2 | H24: =_xlfn.IFS((H23/H19)<75%,"Tier 0",AND((H23/H19)>=75%,(H23/H19)<85%),"Tier 1",AND((H23/H19)>=85%,(H23/H19)<90%),"Tier 2",AND((H23/H19)>=90%,(H23/H19)<100%),"Tier 3",AND((H23/H19)>=100%,(H23/H19)<110%),"Tier 4",(H23/H19)>=110%,"Tier 5") -> Tier 2 | I24: =_xlfn.IFS((I23/I19)<75%,"Tier 0",AND((I23/I19)>=75%,(I23/I19)<85%),"Tier 1",AND((I23/I19)>=85%,(I23/I19)<90%),"Tier 2",AND((I23/I19)>=90%,(I23/I19)<100%),"Tier 3",AND((I23/I19)>=100%,(I23/I19)<110%),"Tier 4",(I23/I19)>=110%,"Tier 4") -> Tier 4 | J24: =_xlfn.IFS((J23/J19)<75%,"Tier 0",AND((J23/J19)>=75%,(J23/J19)<85%),"Tier 1",AND((J23/J19)>=85%,(J23/J19)<90%),"Tier 2",AND((J23/J19)>=90%,(J23/J19)<100%),"Tier 3",AND((J23/J19)>=100%,(J23/J19)<110%),"Tier 4",(J23/J19)>=110%,"Tier 4") -> Tier 3 | K24: Auto-calculation | L24: TC02 | M24: F21
E25: Sequence 2 | F25: Eligible Achievement Incentive | G25: 70000000 | H25: 85000000 | I25: 100000000 | J25: 90000000
E26: Sequence 3 | F26: Paid invoice previous month | G26: 0 | H26: 10000000 | I26: 5000000 | J26: 0
F27: Paid invoice in current month | G27: 60000000 | H27: 70000000 | I27: =IF(I23>I19,I19,70%*I19) -> 100000000 | J27: 65000000 | K27: Auto-calculation
F28: Incentive Payout Previous Month | G28: 0 | H28: =_xlfn.IFS(G24="Tier 0",H26*'Sequential Rule'!$H$5,G24="Tier 1",H26*'Sequential Rule'!$H$6,G24="Tier 2",H26*'Sequential Rule'!$H$7,G24="Tier 3",H26*'Sequential Rule'!$H$8,G24="Tier 4",H26*'Sequential Rule'!$H$9,G24="Tier 5",H26*'Sequential Rule'!$H$10) -> 60000 | I28: =_xlfn.IFS(H24="Tier 0",I26*'Sequential Rule'!$H$5,H24="Tier 1",I26*'Sequential Rule'!$H$6,H24="Tier 2",I26*'Sequential Rule'!$H$7,H24="Tier 3",I26*'Sequential Rule'!$H$8,H24="Tier 4",I26*'Sequential Rule'!$H$9,H24="Tier 5",I26*'Sequential Rule'!$H$10) -> 30000 | J28: =_xlfn.IFS(I24="Tier 0",J26*'Sequential Rule'!$H$5,I24="Tier 1",J26*'Sequential Rule'!$H$6,I24="Tier 2",J26*'Sequential Rule'!$H$7,I24="Tier 3",J26*'Sequential Rule'!$H$8,I24="Tier 4",J26*'Sequential Rule'!$H$9,I24="Tier 5",J26*'Sequential Rule'!$H$10) -> 0
F29: Incentive Payout Current Month | G29: =_xlfn.IFS(G24="Tier 0",G27*'Sequential Rule'!$H$5,'Business Use Case'!G24="Tier 1",'Business Use Case'!G27*'Sequential Rule'!$H$6,'Business Use Case'!G24="Tier 2",'Business Use Case'!G27*'Sequential Rule'!$H$7,'Business Use Case'!G24="Tier 3",'Business Use Case'!G27*'Sequential Rule'!$H$8,'Business Use Case'!G24="Tier 4",'Business Use Case'!G27*'Sequential Rule'!$H$9,'Business Use Case'!G24="Tier 5",'Business Use Case'!G27*'Sequential Rule'!$H$10) -> 360000 | H29: =_xlfn.IFS(H24="Tier 0",H27*'Sequential Rule'!$H$5,'Business Use Case'!H24="Tier 1",'Business Use Case'!H27*'Sequential Rule'!$H$6,'Business Use Case'!H24="Tier 2",'Business Use Case'!H27*'Sequential Rule'!$H$7,'Business Use Case'!H24="Tier 3",'Business Use Case'!H27*'Sequential Rule'!$H$8,'Business Use Case'!H24="Tier 4",'Business Use Case'!H27*'Sequential Rule'!$H$9,'Business Use Case'!H24="Tier 5",'Business Use Case'!H27*'Sequential Rule'!$H$10) -> 420000 | I29: =_xlfn.IFS(I24="Tier 0",I27*'Sequential Rule'!$H$5,'Business Use Case'!I24="Tier 1",'Business Use Case'!I27*'Sequential Rule'!$H$6,'Business Use Case'!I24="Tier 2",'Business Use Case'!I27*'Sequential Rule'!$H$7,'Business Use Case'!I24="Tier 3",'Business Use Case'!I27*'Sequential Rule'!$H$8,'Business Use Case'!I24="Tier 4",'Business Use Case'!I27*'Sequential Rule'!$H$9,'Business Use Case'!I24="Tier 5",'Business Use Case'!I27*'Sequential Rule'!$H$10) -> 750000 | J29: =_xlfn.IFS(J24="Tier 0",J27*'Sequential Rule'!$H$5,'Business Use Case'!J24="Tier 1",'Business Use Case'!J27*'Sequential Rule'!$H$6,'Business Use Case'!J24="Tier 2",'Business Use Case'!J27*'Sequential Rule'!$H$7,'Business Use Case'!J24="Tier 3",'Business Use Case'!J27*'Sequential Rule'!$H$8,'Business Use Case'!J24="Tier 4",'Business Use Case'!J27*'Sequential Rule'!$H$9,'Business Use Case'!J24="Tier 5",'Business Use Case'!J27*'Sequential Rule'!$H$10) -> 438750 | K29: Auto-calculation
F30: Total Incentive Payout | G30: =SUM(G28:G29) -> 360000 | H30: =SUM(H28:H29) -> 480000 | I30: =SUM(I28:I29) -> 780000 | J30: =SUM(J28:J29) -> 438750
F31: Eligible Achievement Bonus | G31: =IF(AND(G20>0,G23>G19),G23-G27,0) -> 0 | H31: =IF(AND(H20>0,H23>H19),H23-H27,0) -> 0 | I31: =IF(AND(I20>0,I23>I19),I23-I27,0) -> 45000000 | J31: =IF(AND(J20>0,J23>J19),J23-J27,0) -> 0 | K31: Auto-calculation
F32: Bonus Payout | G32: =1%*G31 -> 0 | H32: =1%*H31 -> 0 | I32: =1%*I31 -> 450000 | J32: =1%*J31 -> 0 | K32: Auto-calculation
B33: C | C33: Jakarta | D33: Active | F33: Incentive-Based Target Sales | G33: 100000000 | H33: 100000000 | I33: 100000000 | J33: 100000000
F34: Bonus-Based Target Sales | G34: 0 | H34: 0 | I34: =I19/COUNTA($D$19:$D$43) -> 50000000 | J34: =($J$5-$J$61)/COUNTA($C$19:$C$46) -> 30000000
F35: Actual Sales | G35: 100000000 | H35: 95000000 | I35: 100000000 | J35: 120000000
F36: Sales Return Prior/Current in June | G36: 1000000 | H36: 1000000 | I36: 0
F37: Net Sales | G37: 100000000 | H37: =H35-G36-H36 -> 93000000 | I37: =I35-I36 -> 100000000 | J37: 105000000
E38: Sequence 1 | F38: Incentive Tier | G38: =_xlfn.IFS((G37/G33)<75%,"Tier 0",AND((G37/G33)>=75%,(G37/G33)<85%),"Tier 1",AND((G37/G33)>=85%,(G37/G33)<90%),"Tier 2",AND((G37/G33)>=90%,(G37/G33)<100%),"Tier 3",AND((G37/G33)>=100%,(G37/G33)<110%),"Tier 4",(G37/G33)>=110%,"Tier 5") -> Tier 4 | H38: =_xlfn.IFS((H37/H33)<75%,"Tier 0",AND((H37/H33)>=75%,(H37/H33)<85%),"Tier 1",AND((H37/H33)>=85%,(H37/H33)<90%),"Tier 2",AND((H37/H33)>=90%,(H37/H33)<100%),"Tier 3",AND((H37/H33)>=100%,(H37/H33)<110%),"Tier 4",(H37/H33)>=110%,"Tier 5") -> Tier 3 | I38: =_xlfn.IFS((I37/I33)<75%,"Tier 0",AND((I37/I33)>=75%,(I37/I33)<85%),"Tier 1",AND((I37/I33)>=85%,(I37/I33)<90%),"Tier 2",AND((I37/I33)>=90%,(I37/I33)<100%),"Tier 3",AND((I37/I33)>=100%,(I37/I33)<110%),"Tier 4",(I37/I33)>=110%,"Tier 4") -> Tier 4 | J38: =_xlfn.IFS((J37/J33)<75%,"Tier 0",AND((J37/J33)>=75%,(J37/J33)<85%),"Tier 1",AND((J37/J33)>=85%,(J37/J33)<90%),"Tier 2",AND((J37/J33)>=90%,(J37/J33)<100%),"Tier 3",AND((J37/J33)>=100%,(J37/J33)<110%),"Tier 4",(J37/J33)>=110%,"Tier 4") -> Tier 4 | K38: Auto-calculation | L38: TC04 | M38: G31
E39: Sequence 2 | F39: Eligible Achievement Incentive | G39: 60000000 | H39: 80000000 | I39: 90000000 | J39: 100000000
E40: Sequence 3 | F40: Paid invoice previous month | G40: 0 | H40: 0 | I40: 10000000 | J40: 0
F41: Paid invoice in current month | G41: 60000000 | H41: 70000000 | I41: =IF(I37>I33,I33,70%*I33) -> 70000000 | J41: =IF(J37>J33,J33,70%*J33) -> 100000000 | K41: Auto-calculation
...

Sheet UAT Test Cases
A1: Category | B1: TC # | C1: Scenario | D1: Input | E1: Expected Result | F1: Total Payout (refer calculation) | G1: Status (drop-down) | H1: Result (drop-down)
A2: Scenario 1: full incentive-based target | B2: TC01 | C2: Tier 0 | <75% achievement | D2: Sales team = Sales A Sales period= MAY | E2: ='Business Use Case'!G10 -> Tier 0 | F2: ='Business Use Case'!G15 -> 0 | G2: Not Run | H2: "Not Started"
A3: Scenario 1: full incentive-based target | B3: TC02 | C3: Tier 2 | 86% achievement | D3: Sales team = Sales B Sales period= MAY | E3: ='Business Use Case'!G24 -> Tier 2 | F3: ='Business Use Case'!G29 -> 360000 | G3: Not Run | H3: "Not Started"
A4: Scenario 1: full incentive-based target | B4: TC03 | C4: Tier 5 | 110% achievement | D4: Sales team = Sales D Sales period= JULY | E4: ='Business Use Case'!I52 -> Tier 5 | F4: ='Business Use Case'!I57 -> 826875 | G4: Not Run | H4: "Not Started"
A5: Scenario 1: full incentive-based target | B5: TC04 | C5: Tier 3 | 93% achievement | D5: Sales team = Sales C Sales period= JUNE | E5: ='Business Use Case'!H38 -> Tier 3 | F5: ='Business Use Case'!H43 -> 472500 | G5: Not Run | H5: "Not Started"
A6: Scenario 1: full incentive-based target | B6: TC05 | C6: Tier 4 | 100% achievement | D6: Sales team = Sales C Sales period= MAY | E6: ='Business Use Case'!G38 -> Tier 4 | F6: ='Business Use Case'!G43 -> 450000 | G6: Not Run | H6: "Not Started"
A7: Scenario 1: full incentive-based target | B7: TC06 | C7: Tier 1 | 76% achievement | D7: Sales team = Sales D Sales period= JUNE | E7: ='Business Use Case'!H52 -> Tier 1 | F7: ='Business Use Case'!H57 -> 210000 | G7: Not Run | H7: "Not Started"
A8: Scenario 1: full incentive-based target | C8: Discount >35% | D8: 1 sales invoice has 3 lines: SKU A disc 20%, SKU B disc 35%, SKU C disc 60% | E8: SKU A & B eligible; SKU C not eligible | G8: Not Run | H8: "Not Started"
A9: Scenario 1: full incentive-based target | C9: Prior invoice paid later | D9: Previous invoice period paid in current month Previous month performance not achieved - Tier 0 | E9: Total payout only calculate "Paid Invoice in Current Month" | G9: Not Run | H9: "Not Started"
A10: Scenario 1: full incentive-based target | C10: Prior invoice paid later | D10: Previous invoice period paid in current month Previous month performance achieved - Tier 1 and above | E10: Total payout = "Paid Invoice Previous Month" + "Paid Invoice in Current Month" | G10: Not Run | H10: "Not Started"
A11: Scenario 1: full incentive-based target | C11: Customer refund | D11: Sales Return: Previous Month Current Period: Current Month Tiering Not Change | E11: NEED UPDATE | G11: Not Run | H11: "Not Started"
A12: Scenario 1: full incentive-based target | C12: Customer refund | D12: Sales Return: Previous Month Current Period: Current Month Tiering degrading from original achievement before return, but still eligible for incentive | E12: NEED UPDATE | G12: Not Run | H12: "Not Started"
A13: Scenario 1: full incentive-based target | C13: Customer refund | D13: Sales Return: Previous Month Current Period: Current Month Tiering degrading from original achievement before return, no longer eligible for incentive | E13: NEED UPDATE | G13: Not Run | H13: "Not Started"
A14: Resignation | C14: Resignation | D14: Sales team A resigns by end of June Impact to active sales team in respective month | E14: Vacant target redistributed by FTE | G14: Not Run | H14: "Not Started"
A15: Scenario 2: mixed target (incentive-based & bonus-based) | C15: Tier 4 | 100% achievement Bonus achieved | D15: Sales team = Sales C Sales period = August | E15: Payout Rate incentive-based + 1.00% bonus-based | F15: ='Business Use Case'!J44+'Business Use Case'!J46 -> 800000 | G15: Not Run | H15: "Not Started"
A16: Scenario 2: mixed target (incentive-based & bonus-based) | C16: Tier 4 | 100% achievement Bonus not achieved | D16: Sales team = Sales B Sales period = August | E16: Payout Rate incentive-based + 1.00% bonus-based | F16: ='Business Use Case'!J30+'Business Use Case'!J32 -> 438750 | G16: Not Run | H16: "Not Started"
A17: New hire | C17: New hire | D17: Sales team F Join 01 August Effective target 18 August | E17: August target prorated 12/30 Achieved target in tier 1 | F17: ='Business Use Case'!J72 -> 60000 | G17: Not Run | H17: "Not Started"
A18: Scenario 2: mixed target (incentive-based & bonus-based) | C18: Tier 4 | 100% achievement Bonus achieved | D18: Sales Team: B Sales Period: JULY | E18: Payout Rate incentive-based + 1.00% bonus-based | F18: ='Business Use Case'!I30+'Business Use Case'!I32 -> 1230000 | G18: Not Run | H18: "Not Started"
G19: Not Run | H19: "Not Started"
A20: Visibility | C20: Visibility | D20: Salesperson logs in | E20: Only own incentive data visible | G20: Not Run | H20: "Not Started"
A21: Manager visibility | C21: Manager visibility | D21: Manager logs in | E21: Subordinate data visible | G21: Not Run | H21: "Not Started"

Sheet Incentive Scheme
B1: Sales target cascade to sales team divided to 2 categories | I1: Steer Co Recap on incentive discussion: | U1: Kebijakan Refund (Business Risk)
I2: 1 | J2: Eligibility on discount 35% applied for item line (not total invoice). For example: | U2: Type of Stock | V2: Work in Progress | W2: Payment Status | X2: Initiator | Y2: Refund Policy
B3: No | C3: Category | D3: Base Rate | E3: Method | F3: Note | J3: Item | K3: Discount | L3: Price | M3: Total | N3: Rate | O3: Payout Incentive | U3: All Type of stock | V3: Yes | W3: Partial/Fully Paid | X3: Customer | Y3: No Refund
B4: 1 | C4: Incentive-Based Target | D4: 1,5% total | E4: Tiering | F4: Target attached to each active sales team | J4: A | K4: 0.2 | L4: 100000 | M4: =K4*L4 -> 20000 | N4: 0.0075 | O4: =M4*N4 -> 150 | U4: Indent | V4: No | W4: Partial/Fully Paid | X4: Customer | Y4: No Refund
B5: 2 | C5: Bonus-Based Target | D5: tbd | E5: tbd | F5: Target derived from vacant position | J5: B | K5: 0.1 | L5: 500000 | M5: =K5*L5 -> 50000 | N5: 0.0075 | O5: =M5*N5 -> 375 | U5: Available stock | V5: No | W5: Partial/Fully Paid | X5: Customer | Y5: Refund 99%
J6: C | K6: 0.4 | L6: 300000 | M6: =K6*L6 -> 120000 | N6: 0.0075 | O6: 0 | P6: >> not eligible | U6: Jasa Curtain | V6: No | W6: Partial/Fully Paid | X6: Customer | Y6: Refund 99%
B7: Total incentives are sum of 2 categories | M7: =SUM(M4:M6) -> 190000 | U7: Indent | V7: Yes | W7: Partial/Fully Paid | X7: Vania | Y7: Based on agreement
U8: Available stock | V8: Yes | W8: Partial/Fully Paid | X8: Vania | Y8: Based on agreement
B9: No | C9: Category | D9: Base Rate | E9: Method | I9: 2 | J9: Basic logic to translate from branch number to each individual both target and incentives: | U9: Jasa Curtain | V9: Yes | W9: Partial/Fully Paid | X9: Vania | Y9: Based on agreement
B10: 1 | C10: Branch Incentives | D10: 0.0075 | E10: Tiering | J10: - 2H 2026 will use rolling forecast number from Head of Sales' number
B11: 2 | C11: Individual Incentives | D11: 0.0075 | E11: Tiering | J11: - For 2027 budget using FTE (Full Time Equivalent) that divided into 3 levels and 2 business type | U11: Point 5: Simulation between full incentive-based target vs mixed (incentive-based + bonus based target)
C12: Total Incentives | D12: =SUM(D10:D11) -> 0.015
J13: B2B BRANCH INCENTIVE | N13: B2C BRANCH INCENTIVE | U13: Scenario 1 | V13: All achieved target using full incentive-based target | Y13: Scenario 1 | Z13: Scenario 2
B14: Branch Incentives | J14: Designation | K14: FTE | L14: Position | N14: Designation | O14: FTE | P14: Position | U14: Scenario 2 | V14: Achieved target using mix incentive + bonus | X14: Sales Achievement | Y14: =X17 -> 62500000 | Z14: =V17 -> 50000000 | AA14: =W17 -> 12500000 | AB14: =SUM(Z14:AA14) -> 62500000
F15: Base Rate x Allocation | J15: B2B Lead | K15: 1.5 | L15: Sales Manager | N15: B2C Lead | O15: 1.5 | P15: Spv Showroom | X15: Base Rate | Y15: =F32 -> 0.007875 | Z15: =F31 -> 0.0075 | AA15: 0.01
B16: Level | C16: Tiering 75% | D16: Base Rate | E16: Allocation | F16: Payout Rate | G16: Note | J16: B2B Team | K16: 1 | L16: Sales Executive | N16: B2C Team | O16: 1 | P16: CS | U16: Sales Person | V16: Incentive Target | W16: Bonus Target | X16: Total Target | Y16: Incentive 110% | Z16: Incentive 100% | AA16: Bonus | AB16: Total
B17: 0 | C17: <= 75% | D17: 0.0075 | E17: 0 | F17: =D17*E17 -> 0 | G17: Not eligible | J17: B2B Support | K17: 0.25 | L17: Sales Support | N17: B2C Support | O17: 0.25 | P17: Sales Support | U17: A | V17: 50000000 | W17: =($V$21/4) -> 12500000 | X17: =SUM(V17:W17) -> 62500000 | Y17: =$F$32*X17 -> 492187.5 | Z17: =V17*$F$31 -> 375000 | AA17: =$AA$15*W17 -> 125000 | AB17: =Z17+AA17 -> 500000
B18: 1 | C18: 75% - 84.9% | D18: 0.0075 | E18: 0.4 | F18: =D18*E18 -> 0.003 | G18: of revenue achieved | U18: B | V18: 50000000 | W18: =($V$21/4) -> 12500000 | X18: =SUM(V18:W18) -> 62500000 | Y18: =$F$32*X18 -> 492187.5 | Z18: =V18*$F$31 -> 375000 | AA18: =$AA$15*W18 -> 125000 | AB18: =Z18+AA18 -> 500000
B19: 2 | C19: 85% - 89.9% | D19: 0.0075 | E19: 0.8 | F19: =D19*E19 -> 0.006 | G19: of revenue achieved | J19: B2B INDIVIDUAL INCENTIVE | N19: B2C INDIVIDUAL INCENTIVE | U19: C | V19: 50000000 | W19: =($V$21/4) -> 12500000 | X19: =SUM(V19:W19) -> 62500000 | Y19: =$F$32*X19 -> 492187.5 | Z19: =V19*$F$31 -> 375000 | AA19: =$AA$15*W19 -> 125000 | AB19: =Z19+AA19 -> 500000
B20: 3 | C20: 90% - 99.9% | D20: 0.0075 | E20: 0.9 | F20: =D20*E20 -> 0.00675 | G20: of revenue achieved | J20: Designation | K20: FTE | L20: Position | N20: Designation | O20: FTE | P20: Position | U20: D | V20: 50000000 | W20: =($V$21/4) -> 12500000 | X20: =SUM(V20:W20) -> 62500000 | Y20: =$F$32*X20 -> 492187.5 | Z20: =V20*$F$31 -> 375000 | AA20: =$AA$15*W20 -> 125000 | AB20: =Z20+AA20 -> 500000
B21: 4 | C21: 100% - 109.9% | D21: 0.0075 | E21: 1 | F21: =D21*E21 -> 0.0075 | G21: of revenue achieved | J21: B2B Lead | K21: 1.5 | L21: Sales Manager | N21: B2C Lead | O21: 1.5 | P21: Spv Showroom | U21: E | V21: 50000000 | W21: Resign
B22: 5 | C22: >=110% | D22: 0.0075 | E22: 1.05 | F22: =D22*E22 -> 0.007875 | G22: of revenue achieved | J22: B2B Team | K22: 1 | L22: Sales Executive | N22: B2C Team | O22: 1 | P22: CS
J23: B2B Support | K23: 0 | L23: Sales Support | N23: B2C Support | O23: 0 | P23: Sales Support | U23: Point 6: Simulation for target movement for sales person resign, new hiring, and prorate target
B24: Individual Incentives
F25: Base Rate x Allocation | I25: 3 | J25: Sales person have visibility to track their own incentive calculation (not the payout due to tax impact) | U25: TARGET & INCENTIVE SIMULATION
B26: Level | C26: Tiering 75% | D26: Base Rate | E26: Allocation | F26: Payout Rate | G26: Note | I26: 4 | J26: Resigned/Vacant's target will be distributed based on FTE to existing sales team while waiting for new hiring | U26: Sales Person | V26: JULY | W26: AGUSTUS | Z26: SEPTEMBER SCENARIO 1 | AC26: SEPTEMBER SCENARIO 2 (DECISION)
B27: 0 | C27: <= 75% | D27: 0.0075 | E27: 0 | F27: =D27*E27 -> 0 | G27: Not eligible | I27: 5 | J27: When Incentive-Based Target + Bonus-Based Target fully achieved, VIF will use Scenario 2: | V27: Original | W27: Original | X27: Bonus | Y27: Total | Z27: Original | AA27: Bonus | AB27: Total | AC27: Original | AD27: Bonus | AE27: Total
B28: 1 | C28: 75% - 84.9% | D28: 0.0075 | E28: 0.4 | F28: =D28*E28 -> 0.003 | G28: of revenue achieved | J28: Target Sales | L28: Base Rate | U28: A | V28: 50000000 | W28: 50000000 | X28: =$V$32/4 -> 12500000 | Y28: =SUM(W28:X28) -> 62500000 | Z28: 50000000 | AA28: 0 | AB28: =SUM(Z28:AA28) -> 50000000 | AC28: 50000000 | AD28: =($V$32-$AC$33)/4 -> 6250000 | AE28: =SUM(AC28:AD28) -> 56250000
B29: 2 | C29: 85% - 89.9% | D29: 0.0075 | E29: 0.8 | F29: =D29*E29 -> 0.006 | G29: of revenue achieved | J29: Incentive-based target | L29: 0.0075 | M29: Tiering level 5 will not be applicable | U29: B | V29: 50000000 | W29: 50000000 | X29: =$V$32/4 -> 12500000 | Y29: =SUM(W29:X29) -> 62500000 | Z29: 50000000 | AA29: 0 | AB29: =SUM(Z29:AA29) -> 50000000 | AC29: 50000000 | AD29: =($V$32-$AC$33)/4 -> 6250000 | AE29: =SUM(AC29:AD29) -> 56250000
B30: 3 | C30: 90% - 99.9% | D30: 0.0075 | E30: 0.9 | F30: =D30*E30 -> 0.00675 | G30: of revenue achieved | J30: Bonus-based target | L30: 0.01 | U30: C | V30: 50000000 | W30: 50000000 | X30: =$V$32/4 -> 12500000 | Y30: =SUM(W30:X30) -> 62500000 | Z30: 50000000 | AA30: 0 | AB30: =SUM(Z30:AA30) -> 50000000 | AC30: 50000000 | AD30: =($V$32-$AC$33)/4 -> 6250000 | AE30: =SUM(AC30:AD30) -> 56250000
B31: 4 | C31: 100% - 109.9% | D31: 0.0075 | E31: 1 | F31: =D31*E31 -> 0.0075 | G31: of revenue achieved | J31: Total Base Rate | L31: =L30+L29 -> 0.0175 | M31: Refer to this calculation | U31: D | V31: 50000000 | W31: 50000000 | X31: =$V$32/4 -> 12500000 | Y31: =SUM(W31:X31) -> 62500000 | Z31: 50000000 | AA31: 0 | AB31: =SUM(Z31:AA31) -> 50000000 | AC31: 50000000 | AD31: =($V$32-$AC$33)/4 -> 6250000 | AE31: =SUM(AC31:AD31) -> 56250000
B32: 5 | C32: >=110% | D32: 0.0075 | E32: 1.05 | F32: =D32*E32 -> 0.007875 | G32: of revenue achieved | U32: E | V32: 50000000 | W32: RESIGN | Z32: 0 | AB32: =SUM(Z32:AA32) -> 0 | AC32: 0 | AD32: 0 | AE32: =SUM(AC32:AD32) -> 0
I33: 6 | J33: Prorate target implemented if new hiring joined in mid month | U33: F | V33: Masuk tgl 15 Sep | W33: =V43*(15/30) -> 0 | X33: =V43/2 -> 0 | Y33: =SUM(W33:X33) -> 0 | Z33: =V32*(15/30) -> 25000000 | AA33: =V32/2 -> 25000000 | AB33: =SUM(Z33:AA33) -> 50000000 | AC33: =Z33 -> 25000000 | AD33: =Y32/2 -> 0 | AE33: =SUM(AC33:AD33) -> 25000000
B34: Decision Tree - Sequential | J34: Decision: SCENARIO 2 | M34: Refer to this calculation | V34: Total Sales Achieve | W34: =SUM(W28:W33) -> 200000000 | X34: =SUM(X28:X33) -> 50000000 | Y34: =SUM(Y28:Y33) -> 250000000 | Z34: =SUM(Z28:Z33) -> 225000000 | AA34: =SUM(AA28:AA33) -> 25000000 | AB34: =SUM(AB28:AB33) -> 250000000 | AC34: =SUM(AC28:AC33) -> 225000000 | AD34: =SUM(AD28:AD33) -> 25000000 | AE34: =SUM(AE28:AE33) -> 250000000
V35: Base Rate Incentive | W35: 0.0075 | X35: 0.01 | Z35: 0.0075 | AA35: 0.01 | AC35: 0.0075 | AD35: 0.01
I36: Possible Pain Points | V36: Payout Incentive | W36: =W34*W35 -> 1500000 | X36: =X34*X35 -> 500000 | Z36: =Z34*Z35 -> 1687500 | AA36: =AA34*AA35 -> 250000 | AC36: =AC34*AC35 -> 1687500 | AD36: =AD34*AD35 -> 250000
I37: 1 | J37: Multi iteration calculation untuk periode lalu hingga semua SO pada periode lalu sudah di-paid
J38: VIF: how the system able to accommodate the capacity?
J39: LID: Odoo able to accommodate
I40: 2 | J40: The system must acknowledge the eligible months for incentives?
...

Sheet Scenario Matrix Guide
A1: ODOO INCENTIVE SETUP – SCENARIO MATRIX GUIDE
A2: Purpose | B2: Bridge between business incentive policy and Odoo functional/technical requirements.
A3: Primary use | B3: Finance and sales module, Odoo alignment, solution design, development scoping, UAT and go-live controls.
A5: Column | B5: Detailed explanation
A6: ID | B6: Unique scenario identifier for discussion, development and UAT sign-off.
A7: Scenario / Business Rule | B7: The business requirement or exception that Odoo must support.
A8: Trigger / Driver / Input | B8: The event/data condition that activates the rule, e.g. achievement, payment, discount, refund, resignation or new hire.
A9: Odoo Setup / Object | B9: The Odoo object, configuration, automation or custom model supporting the rule.
A10: Calculation / Logic | B10: The functional logic Odoo must apply
A11: Expected Result | B11: Expected Finance/Sales outcome and UAT acceptance result.
A12: Standard Odoo | B12: Whether the requirement can reasonably be handled by standard Odoo.
A13: Customization | B13: Whether custom development is recommended.
A14: Priority | B14: Critical = required for correct calculation/go-live. High = important control/functionality.
A16: How to read the matrix
A17: S01–S03 | B17: Target structure, target ownership and target allocation.
A18: S04–S06 | B18: Core incentive engine: achievement tier, base rate and incentive components.
A19: S07 | B19: Critical eligibility gate: invoice lines with discount >35% are excluded from eligible incentive.
A20: S08–S09 | B20: Payment-based mechanism: prior-period invoices become eligible when paid while retaining source-period tagging.
A21: S10–S12 | B21: Refund/cancellation treatment and audit linkage to original incentive transactions.
A22: S13–S15 | B22: Resignation, vacancy redistribution, new hire proration and effective-date target movement.
A23: S16–S18 | B23: Scenario 1 vs Scenario 2 and special treatment of Tier 5 in mixed scenario.
A24: S19–S20 | B24: Role-based visibility for salesperson and manager.
A25: S21–S22 | B25: Period tagging, calculation versioning, auditability and Finance reconciliation.
A26: Recommended architecture
A27: Layer 1 – Transaction source | B27: Standard Odoo Sales, Invoice, Invoice Line, Payment, Credit Note, Employee and Sales Team.
A28: Layer 2 – Incentive master | B28: Custom Incentive Period, Incentive Target, Incentive Rule/Tier, Scenario and Refund Policy.
A29: Layer 3 – Incentive transaction | B29: Custom invoice-line-level transaction linked to salesperson, source period, payment period, eligibility and payout.
A30: Layer 4 – Adjustment | B30: Custom handling for refund, cancellation, resignation, vacancy redistribution, new hire and prior-period payment.
A31: Layer 5 – Reporting | B31: Salesperson/manager dashboard, Finance reconciliation and approved payout report.
A32: Key control principle | B32: Never overwrite historical incentive transactions. Use linked adjustment/reversal transactions for traceability.
A33: Key design principle | B33: Separate source transaction period, payment period and payout period to prevent historical reporting distortion.

Sheet End-to-End Process
A1: Step | B1: Process | C1: System Action | D1: Control / Output
A2: 1 | B2: Set incentive period | C2: Create/open monthly incentive period | D2: One period only can be approved
A3: 2 | B3: Load branch/team target | C3: Input rolling forecast | D3: Target version recorded
A4: 3 | B4: Cascade target | C4: Calculate FTE allocation and/or plug in number | D4: Individual target generated
A5: 4 | B5: Assign scenario | C5: Select Full Incentive or Mixed | D5: Scenario locked before calculation
A6: 5 | B6: Capture sales performance | C6: Read posted invoice lines | D6: Factor in all discount and payment status
A7: 6 | B7: Check achievement | C7: Compare actual eligible revenue vs target | D7: - Tag performance result (eligible/not eligible) - Tier selected
A8: 7 | B8: Capture fully paid invoice | C8: Read fully paid invoice in current period | D8: Check if respective month eligible for incentive
A9: 8 | B9: Check discount eligibility | C9: Evaluate each invoice line <=35% | D9: Eligible flag
A10: 9 | B10: Check payment | C10: Read payment status/date with "Fully Paid" status | D10: Payout eligibility determined
A11: 10 | B11: Apply prior-period transactions | C11: Bring forward newly paid invoices | D11: Original incentive month retained
A12: 11 | B12: Apply refund/cancel | C12: Create reversal/adjustment | D12: Linked to original transaction
A13: 12 | B13: Handle resignation/new hire | C13: Reallocate/prorate target | D13: Effective-date audit trail
... A18: 17 | B18: Final payout calculation | C18: Visible for self-viewed sales person and C-Level | D18: Calculation must not change in the following months

Sheet Odoo Setup Objects
A1: Odoo Object | B1: Purpose | C1: Key Fields | D1: Implementation
A2: Sales Team - Structure | B2: Branch to team hierarchy for FTE | C2: Business type, branch manager, sales team, sales support | D2: Setting in Odoo access role
A3: Sales Team - List of user | B3: Salesperson master | C3: Sales organization structure, sales person, c-level, effective target start date, employment status (active/resign) | D3: Odoo configuration
A4: Incentive Period | B4: Control incentive month | C4: Month, start date, end date, status, rule version Multi-iteration impact | D4: Custom model
A5: Incentive Target | B5: - Branch target cascaded to invidual - Incentive-based and Bonus-based target | C5: Employee, team, period, target type, amount, source | D5: Custom model
A6: Incentive Rule | B6: Tier/rate master | C6: Achievement min/max, base rate, payout allocation %, sequential rules | D6: Custom model
A7: Incentive Transactions | B7: Sales invoice-level incentive basis | C7: Invoice line, sales person, original month, payment month, eligible flag, payout | D7: Custom model
A8: Target Movement | B8: Target transfer history due to: - Rolling forecast (impact on incentive-based target) - Sales team movement (impact on bonus-based target) | C8: Distribute target: - From vacant to active employee - From resigned employee to active employee - Effective target start date | D8: Custom model
A9: Refund policy | B9: Refund rule matrix | C9: Payment status, initiator, refund % Sales return of prior period will impact to current period | D9: Custom model
A10: Incentive data | B10: Invoice & credit note source | C10: Invoice, line, discount, payment status, credit note link | D10: Standard Odoo
A11: Payment Status | B11: Payment trigger | C11: Payment date, invoice link, amount | D11: Standard Odoo
A12: Dashboard / reporting | B12: Visibility | C12: User hierarchy, period, achievement, incentive | D12: Odoo dashboard Custom reporting (if required)

Sheet Legend
A1: Status | B1: Meaning
A2: Standard Odoo | B2: Can be achieved mainly through standard Odoo configuration/reporting
A3: Partial | B3: Standard Odoo provides source data/access, but incentive logic requires configuration or development
A4: Customization | B4: Custom model/automation/report is recommended
A5: Critical | B5: Must be resolved for go-live
A6: High | B6: Important but can be phased if necessary
